Traceback (most recent call last):
  File "/home/gerardoroadabike/anaconda3/envs/clarity39/lib/python3.10/site-packages/jupyter_cache/executors/utils.py", line 58, in single_nb_execution
    executenb(
  File "/home/gerardoroadabike/anaconda3/envs/clarity39/lib/python3.10/site-packages/nbclient/client.py", line 1314, in execute
    return NotebookClient(nb=nb, resources=resources, km=km, **kwargs).execute()
  File "/home/gerardoroadabike/anaconda3/envs/clarity39/lib/python3.10/site-packages/jupyter_core/utils/__init__.py", line 165, in wrapped
    return loop.run_until_complete(inner)
  File "/home/gerardoroadabike/anaconda3/envs/clarity39/lib/python3.10/asyncio/base_events.py", line 649, in run_until_complete
    return future.result()
  File "/home/gerardoroadabike/anaconda3/envs/clarity39/lib/python3.10/site-packages/nbclient/client.py", line 709, in async_execute
    await self.async_execute_cell(
  File "/home/gerardoroadabike/anaconda3/envs/clarity39/lib/python3.10/site-packages/nbclient/client.py", line 1062, in async_execute_cell
    await self._check_raise_for_error(cell, cell_index, exec_reply)
  File "/home/gerardoroadabike/anaconda3/envs/clarity39/lib/python3.10/site-packages/nbclient/client.py", line 918, in _check_raise_for_error
    raise CellExecutionError.from_cell_and_msg(cell, exec_reply_content)
nbclient.exceptions.CellExecutionError: An error occurred while executing the following cell:
------------------
%%shell
python enhance.py \
path.root=$NBOOKROOT \
path.metadata_dir="$\{path.root\}/clarity_data/demo/metadata" \
path.scenes_listeners_file="$\{path.metadata_dir\}/scenes_listeners.demo.json" \
path.listeners_file="$\{path.metadata_dir\}/listeners.json" \
path.scenes_folder="$\{path.root\}/clarity_data/demo/scenes" 

------------------

----- stderr -----
UsageError: Cell magic `%%shell` not found.
------------------



